<?xml version="1.0"?>
<robot name="mr_CCMDX1">

<material name="navy">
    <color rgba="0 0 128 50"/>
  </material>
  <material name="black">
    <color rgba="0 0 0 50"/>
  </material>
  <material name="fucsia">
    <color rgba="255 0 255 1"/>
  </material>
  <material name="white">
    <color rgba="255 255 255 1"/>
  </material>



  <link name="base_link">
    <visual>
      <geometry>
        <cylinder length="0.2" radius="0.2"/>
      </geometry>
      <origin rpy="0 0 0" xyz="0 0 0.15"/>
      <material name="fucsia"/>
    </visual>
    <collision>
      <geometry>
        <cylinder length="0.2" radius="0.2"/>
      </geometry>
    <origin rpy="0 0 0" xyz="0 0 0.15"/>
    </collision>
    <inertial>
      <mass value="10"/>
      <inertia ixx="1" ixy="0.0" ixz="0.0" iyy="1" iyz="0.0" izz="1"/>
    </inertial>
  </link>



  <link name="right_leg">
    <visual>
      <geometry>
        <box size="0.2 0.1 0.1"/>
      </geometry>
      <origin rpy="0 1.57075 0" xyz="0 0 0"/>
      <material name="black"/>
    </visual>
    <collision>
      <geometry>
        <box size="0.2 0.1 0.1"/>
      </geometry>
      <origin rpy="0 1.57075 0" xyz="0 0 0"/>
    </collision>
    <inertial>
      <mass value="10"/>
      <inertia ixx="1" ixy="0.0" ixz="0.0" iyy="1" iyz="0.0" izz="1"/>
    </inertial>
  </link>
  <joint name="base_to_right_leg" type="fixed">
    <parent link="base_link"/>
    <child link="right_leg"/>
    <origin xyz="0 -0.22 0.18"/>
  </joint>

  <link name="right_round_base">
    <visual>
     <geometry>
      <cylinder length="0.1" radius="0.12"/>
     </geometry>
     <origin rpy="1.57075 1.57075 0" xyz="0 0 0"/>
     <material name="navy"/>
    </visual>
    <collision>
      <geometry>
   <cylinder length="0.1" radius="0.12"/>
      </geometry>
    <origin rpy="1.57075 1.57075 0" xyz="0 0 0"/>
    </collision>
    <inertial>
      <mass value="10"/>
      <inertia ixx="1" ixy="0.0" ixz="0.0" iyy="1" iyz="0.0" izz="1"/>
    </inertial>
  </link>
  <joint name="right_round_base_joint" type="fixed">
    <parent link="right_leg"/>
    <child link="right_round_base"/>
    <origin xyz="0 -0.05 -0.09"/>
  </joint>

  <link name="right_box_base">
    <visual>
     <geometry>
       <box size="0.238 0.1 0.14"/>
     </geometry>
     <origin rpy="0 0 0" xyz="0 0 0"/>
     <material name="navy"/>
    </visual>
    <collision>
      <geometry>
       <box size="0.238 0.1 0.14"/>
      </geometry>
    </collision>
    <inertial>
      <mass value="10"/>
      <inertia ixx="1" ixy="0.0" ixz="0.0" iyy="1" iyz="0.0" izz="1"/>
    </inertial>
  </link>
  <joint name="right_box_ base_joint" type="fixed">
    <parent link="right_round_base"/>
    <child link="right_box_base"/>
    <origin xyz="0 0 -0.05"/>
  </joint>

  <link name="right_front_wheel">
    <visual>
      <origin rpy="1.57075 0 0" xyz="0 0 0"/>
      <geometry>
        <cylinder length="0.08" radius="0.035"/>
      </geometry>
      <material name="black"/>
    </visual>
    <collision>
      <origin rpy="1.57075 0 0" xyz="0 0 0"/>
      <geometry>
        <cylinder length="0.08" radius="0.035"/>
      </geometry>
    </collision>
    <inertial>
      <mass value="4"/>
      <inertia ixx="1.0" ixy="0.0" ixz="0.0" iyy="1.0" iyz="0.0" izz="1.0"/>
    </inertial>
  </link>

    <gazebo reference="$right_front_wheel">
      <mu1 value="200.0"/>
      <mu2 value="100.0"/>
      <kp value="10000000.0" />
      <kd value="1.0" />
      <material>Gazebo/Grey</material>
    </gazebo>

  <joint name="right_front_wheel_joint" type="continuous">
    <axis rpy="0 0 0" xyz="0 1 0"/>
    <parent link="right_box_base"/>
    <child link="right_front_wheel"/>
    <origin rpy="0 0 0" xyz="0.08 0 -0.076"/>
  </joint>

  <!-- This block connects the transmission for the robot wheels, joint to an actuator (motor), which informs both simulation and visualization of the robot. For now I dropped xacro  -->

    <transmission name="right_front_wheel_trans">
      <type>transmission_interface/SimpleTransmission</type>
      <actuator name="right_front_wheel_motor">
        <mechanicalReduction>1</mechanicalReduction>
      </actuator>
      <joint name="right_front_wheel_joint">
        <hardwareInterface>hardware_interface/VelocityJointInterface</hardwareInterface>
      </joint>
    </transmission>

  <link name="right_back_wheel">
    <visual>
      <origin rpy="1.57075 0 0" xyz="0 0 0"/>
      <geometry>
        <cylinder length="0.08" radius="0.035"/>
      </geometry>
      <material name="black"/>
    </visual>
    <collision>
      <origin rpy="1.57075 0 0" xyz="0 0 0"/>
      <geometry>
        <cylinder length="0.08" radius="0.035"/>
      </geometry>
    </collision>
    <inertial>
      <mass value="4"/>
      <inertia ixx="1.0" ixy="0.0" ixz="0.0" iyy="1.0" iyz="0.0" izz="1.0"/>
    </inertial>
  </link>

    <gazebo reference="$right_back_wheel">
      <mu1 value="200.0"/>
      <mu2 value="100.0"/>
      <kp value="10000000.0" />
      <kd value="1.0" />
      <material>Gazebo/Grey</material>
    </gazebo>

  <joint name="right_back_wheel_joint" type="continuous">
    <axis rpy="0 0 0" xyz="0 1 0"/>
    <parent link="right_box_base"/>
    <child link="right_back_wheel"/>
    <origin rpy="0 0 0" xyz="-0.08 0 -0.076"/>
  </joint>

  <!-- This block connects the transmission for the robot wheels, joint to an actuator (motor), which informs both simulation and visualization of the robot. For now I dropped xacro  -->

    <transmission name="right_back_wheel_trans">
      <type>transmission_interface/SimpleTransmission</type>
      <actuator name="right_back_wheel_motor">
        <mechanicalReduction>1</mechanicalReduction>
      </actuator>
      <joint name="right_back_wheel_joint">
        <hardwareInterface>hardware_interface/VelocityJointInterface</hardwareInterface>
      </joint>
    </transmission>

  <link name="left_leg">
    <visual>
      <geometry>
        <box size="0.2 0.1 0.1"/>
      </geometry>
      <origin rpy="0 1.57075 0" xyz="0 0 0"/>
      <material name="black"/>
    </visual>
    <collision>
      <geometry>
        <box size="0.2 0.1 0.1"/>
      </geometry>
      <origin rpy="0 1.57075 0" xyz="0 0 0"/>
    </collision>
    <inertial>
      <mass value="10"/>
      <inertia ixx="1" ixy="0.0" ixz="0.0" iyy="1" iyz="0.0" izz="1"/>
    </inertial>
  </link>
  <joint name="base_to_left_leg" type="fixed">
    <parent link="base_link"/>
    <child link="left_leg"/>
    <origin xyz="0 0.22 0.18"/>
  </joint>

<link name="left_round_base">
    <visual>
     <geometry>
      <cylinder length="0.1" radius="0.12"/>
     </geometry>
     <origin rpy="1.57075 1.57075 0" xyz="0 0 0"/>
     <material name="navy"/>
    </visual>
    <collision>
      <geometry>
   <cylinder length="0.1" radius="0.12"/>
      </geometry>
     <origin rpy="1.57075 1.57075 0" xyz="0 0 0"/>
    </collision>
    <inertial>
      <mass value="10"/>
      <inertia ixx="1" ixy="0.0" ixz="0.0" iyy="1" iyz="0.0" izz="1"/>
    </inertial>
  </link>
  <joint name="left_round_base_joint" type="fixed">
    <parent link="left_leg"/>
    <child link="left_round_base"/>
    <origin xyz="0 0.05 -0.09"/>
  </joint>

 <link name="left_box_base">
    <visual>
     <geometry>
       <box size="0.238 0.1 0.14"/>
     </geometry>
     <origin rpy="0 0 0" xyz="0 0 0"/>
     <material name="navy"/>
    </visual>
    <collision>
      <geometry>
       <box size="0.238 0.1 0.14"/>
      </geometry>
    </collision>
    <inertial>
      <mass value="10"/>
      <inertia ixx="1" ixy="0.0" ixz="0.0" iyy="1" iyz="0.0" izz="1"/>
    </inertial>
  </link>
  <joint name="left_box_ base_joint" type="fixed">
    <parent link="left_round_base"/>
    <child link="left_box_base"/>
    <origin xyz="0 0 -0.05"/>
  </joint>

  <link name="left_front_wheel">
    <visual>
      <origin rpy="1.57075 0 0" xyz="0 0 0"/>
      <geometry>
        <cylinder length="0.08" radius="0.035"/>
      </geometry>
      <material name="black"/>
    </visual>
    <collision>
      <origin rpy="1.57075 0 0" xyz="0 0 0"/>
      <geometry>
        <cylinder length="0.08" radius="0.035"/>
      </geometry>
    </collision>
    <inertial>
      <mass value="4"/>
      <inertia ixx="1.0" ixy="0.0" ixz="0.0" iyy="1.0" iyz="0.0" izz="1.0"/>
    </inertial>
  </link>

    <gazebo reference="$left_front_wheel">
      <mu1 value="200.0"/>
      <mu2 value="100.0"/>
      <kp value="10000000.0" />
      <kd value="1.0" />
      <material>Gazebo/Grey</material>
    </gazebo>

  <joint name="left_front_wheel_joint" type="continuous">
    <axis rpy="0 0 0" xyz="0 1 0"/>
    <parent link="left_box_base"/>
    <child link="left_front_wheel"/>
    <origin rpy="0 0 0" xyz="0.08 0 -0.076"/>
  </joint>

  <!-- This block connects the transmission for the robot wheels, joint to an actuator (motor), which informs both simulation and visualization of the robot. For now I dropped xacro  -->

    <transmission name="left_front_wheel_trans">
      <type>transmission_interface/SimpleTransmission</type>
      <actuator name="left_front_wheel_trans">
        <mechanicalReduction>1</mechanicalReduction>
      </actuator>
      <joint name="left_front_wheel_joint">
        <hardwareInterface>hardware_interface/VelocityJointInterface</hardwareInterface>
      </joint>
    </transmission>

  <link name="left_back_wheel">
    <visual>
      <origin rpy="1.57075 0 0" xyz="0 0 0"/>
      <geometry>
        <cylinder length="0.08" radius="0.035"/>
      </geometry>
      <material name="black"/>
    </visual>
    <collision>
      <origin rpy="1.57075 0 0" xyz="0 0 0"/>
      <geometry>
        <cylinder length="0.08" radius="0.035"/>
      </geometry>
    </collision>
    <inertial>
      <mass value="4"/>
      <inertia ixx="1.0" ixy="0.0" ixz="0.0" iyy="1.0" iyz="0.0" izz="1.0"/>
    </inertial>
  </link>

    <gazebo reference="$left_back_wheel">
      <mu1 value="200.0"/>
      <mu2 value="100.0"/>
      <kp value="10000000.0" />
      <kd value="1.0" />
      <material>Gazebo/Grey</material>
    </gazebo>

  <joint name="left_back_wheel_joint" type="continuous">
    <axis rpy="0 0 0" xyz="0 1 0"/>
    <parent link="left_box_base"/>
    <child link="left_back_wheel"/>
    <origin rpy="0 0 0" xyz="-0.08 0 -0.076"/>
  </joint>

  <!-- This block connects the transmission for the robot wheels, joint to an actuator (motor),which informs both simulation and visualization of the robot. For now I dropped xacro  -->

    <transmission name="left_back_wheel_trans">
      <type>transmission_interface/SimpleTransmission</type>
      <actuator name="left_back_wheel_trans">
        <mechanicalReduction>1</mechanicalReduction>
      </actuator>
      <joint name="left_back_wheel_joint">
        <hardwareInterface>hardware_interface/VelocityJointInterface</hardwareInterface>
      </joint>
    </transmission>

  <link name="robot_head_link">
    <visual>
      <geometry>
        <sphere radius="0.2"/>
      </geometry>
      <material name="black"/>
    </visual>
    <collision>
      <geometry>
        <sphere radius="0.2"/>
      </geometry>
    </collision>
    <inertial>
      <mass value="5"/>
      <inertia ixx="1.0" ixy="0.0" ixz="0.0" iyy="1.0" iyz="0.0" izz="1.0"/>
    </inertial>
  </link>

  <joint name="head_swivel_joint" type="continuous">
    <parent link="base_link"/>
    <child link="robot_head_link"/>
    <axis xyz="0 0 1"/>
    <origin xyz="0 0 0.25"/>
    <limit effort="50" velocity="0.5"/>
  </joint>


  <!-- This block connects the head_swivel joint to an actuator (motor), which informs both simulation and visualization of the robot -->
  <transmission name="head_swivel_trans">
    <type>transmission_interface/SimpleTransmission</type>
    <actuator name="$head_swivel_motor">
      <mechanicalReduction>1</mechanicalReduction>
    </actuator>
    <joint name="head_swivel_joint">
      <!--hardwareInterface>hardware_interface/PositionJointInterface</hardwareInterface-->
	<hardwareInterface>hardware_interface/PositionJointInterface</hardwareInterface>
    </joint>
  </transmission>

  <joint name="camera_box_joint" type="fixed">
   <axis xyz="0 1 0" />
    <parent link="robot_head_link"/>
    <child link="camera_link"/>
    <origin xyz="0.1814 0 0.1414"/>
  </joint>

  <link name="camera_link">
   <visual>
    <geometry>
     <box size="0.08 0.08 0.08"/>
    </geometry>
    <material name="navy"/>
    <origin xyz="-0.04 0 0"/>
    </visual>
     <collision>
      <geometry>
       <box size="0.08 0.08 0.08"/>
      </geometry>
     </collision>
     <inertial>
      <mass value="1"/>
      <inertia ixx="1.0" ixy="0.0" ixz="0.0" iyy="1.0" iyz="0.0" izz="1.0"/>
     </inertial>
  </link>

<!-- camera -->
  <gazebo reference="camera_link">
    <sensor type="camera" name="camera1">
      <update_rate>30.0</update_rate>
      <camera name="head_camera">
        <horizontal_fov>1.3962634</horizontal_fov>
        <image>
          <width>800</width>
          <height>800</height>
          <format>R8G8B8</format>
        </image>
        <clip>
          <near>0.02</near>
          <far>300</far>
        </clip>
        <noise>
          <type>gaussian</type>
          <!-- Noise is sampled independently per pixel on each frame.
               That pixel's noise value is added to each of its color
               channels, which at that point lie in the range [0,1]. -->
          <mean>0.0</mean>
          <stddev>0.007</stddev>
        </noise>
      </camera>
      <plugin name="camera_controller" filename="libgazebo_ros_camera.so">
        <alwaysOn>true</alwaysOn>
        <updateRate>0.0</updateRate>
        <cameraName>ccmdx1/camera1</cameraName>
        <imageTopicName>image_raw</imageTopicName>
        <cameraInfoTopicName>camera_info</cameraInfoTopicName>
        <frameName>camera_link</frameName>
        <hackBaseline>0.07</hackBaseline>
        <distortionK1>0.0</distortionK1>
        <distortionK2>0.0</distortionK2>
        <distortionK3>0.0</distortionK3>
        <distortionT1>0.0</distortionT1>
        <distortionT2>0.0</distortionT2>
      </plugin>
    </sensor>
  </gazebo>

 <joint name="head_laser_sensor_joint" type="fixed">
    <axis xyz="0 0 0" />
    <origin xyz="0 0 0.23"/>
    <parent link="robot_head_link"/>
    <child link="hokuyo_link"/>
  </joint>

  <!-- Hokuyo Laser -->
  <link name="hokuyo_link">
   <origin xyz="0 0 0" rpy="0 0 0"/>
    <collision>
      <origin xyz="0 0 0.0" rpy="0 0 0"/>
      <geometry>
       <box size="0.1 0.1 0.1"/>
      </geometry>
    </collision>
    <visual>
      <origin xyz="0 0 0" rpy="0 0 0"/>
      <material name="white"/>
      <geometry>
        <mesh filename="package://mobile_robot_CCMDX1/meshes/hokuyo.dae"/>
      </geometry>
    </visual>
    <inertial>
      <mass value="1e-5" />
      <origin xyz="0 0 0" rpy="0 0 0"/>
      <inertia ixx="1e-6" ixy="0" ixz="0" iyy="1e-6" iyz="0" izz="1e-6" />
    </inertial>
  </link>

<!-- hokuyo -->
  <gazebo reference="hokuyo_link">
    <sensor type="gpu_ray" name="head_hokuyo_sensor">
      <pose>0 0 0.23 0 0 0</pose>
      <visualize>false</visualize>
      <update_rate>40</update_rate>
      <ray>
        <scan>
          <horizontal>
            <samples>720</samples>
            <resolution>1</resolution>
            <min_angle>-1.570796</min_angle>
            <max_angle>1.570796</max_angle>
          </horizontal>
        </scan>
        <range>
          <min>0.10</min>
          <max>30.0</max>
          <resolution>0.01</resolution>
        </range>
        <noise>
          <type>gaussian</type>
          <!-- Noise parameters based on published spec for Hokuyo laser
               achieving "+-30mm" accuracy at range < 10m.  A mean of 0.0m and
               stddev of 0.01m will put 99.7% of samples within 0.03m of the true
               reading. -->
          <mean>0.0</mean>
          <stddev>0.01</stddev>
        </noise>
      </ray>
      <plugin name="gazebo_ros_head_hokuyo_controller" filename="libgazebo_ros_gpu_laser.so">
        <topicName>/rrbot/laser/scan</topicName>
        <frameName>hokuyo_link</frameName>
      </plugin>
    </sensor>
  </gazebo>




















  <gazebo>
    <plugin name="gazebo_ros_control" filename="libgazebo_ros_control.so">
      <robotNamespace>/</robotNamespace>
    </plugin>
  </gazebo>



</robot>
